<sdf version='1.6'>
  <world name='default'>
    <light name='sun' type='directional'>
      <cast_shadows>1</cast_shadows>
      <pose frame=''>0 0 10 0 -0 0</pose>
      <diffuse>0.8 0.8 0.8 1</diffuse>
      <specular>0.2 0.2 0.2 1</specular>
      <attenuation>
        <range>1000</range>
        <constant>0.9</constant>
        <linear>0.01</linear>
        <quadratic>0.001</quadratic>
      </attenuation>
      <direction>-0.5 0.1 -0.9</direction>
    </light>
    <model name='ground_plane'>
      <static>1</static>
      <link name='link'>
        <collision name='collision'>
          <geometry>
            <plane>
              <normal>0 0 1</normal>
              <size>100 100</size>
            </plane>
          </geometry>
          <surface>
            <contact>
              <collide_bitmask>65535</collide_bitmask>
              <ode/>
            </contact>
            <friction>
              <ode>
                <mu>100</mu>
                <mu2>50</mu2>
              </ode>
              <torsional>
                <ode/>
              </torsional>
            </friction>
            <bounce/>
          </surface>
          <max_contacts>10</max_contacts>
        </collision>
        <visual name='visual'>
          <cast_shadows>0</cast_shadows>
          <geometry>
            <plane>
              <normal>0 0 1</normal>
              <size>100 100</size>
            </plane>
          </geometry>
          <material>
            <script>
              <uri>file://media/materials/scripts/gazebo.material</uri>
              <name>Gazebo/Grey</name>
            </script>
          </material>
        </visual>
        <self_collide>0</self_collide>
        <enable_wind>0</enable_wind>
        <kinematic>0</kinematic>
      </link>
    </model>
    <gravity>0 0 -9.8</gravity>
    <magnetic_field>6e-06 2.3e-05 -4.2e-05</magnetic_field>
    <atmosphere type='adiabatic'/>
    <physics name='default_physics' default='0' type='ode'>
      <max_step_size>0.001</max_step_size>
      <real_time_factor>1</real_time_factor>
      <real_time_update_rate>1000</real_time_update_rate>
    </physics>
    <scene>
      <ambient>0.4 0.4 0.4 1</ambient>
      <background>0.7 0.7 0.7 1</background>
      <shadows>1</shadows>
    </scene>
    <audio>
      <device>default</device>
    </audio>
    <wind/>
    <spherical_coordinates>
      <surface_model>EARTH_WGS84</surface_model>
      <latitude_deg>0</latitude_deg>
      <longitude_deg>0</longitude_deg>
      <elevation>0</elevation>
      <heading_deg>0</heading_deg>
    </spherical_coordinates>
    <model name='robot'>
      <link name='robot_base_footprint'>
        <pose frame=''>0 0 0 0 -0 0</pose>
        <inertial>
          <pose frame=''>0.007857 -1.1e-05 0.114487 0 -0 0</pose>
          <mass>25.667</mass>
          <inertia>
            <ixx>1.41577</ixx>
            <ixy>0.00408536</ixy>
            <ixz>-0.0326829</ixz>
            <iyy>6.9357</iyy>
            <iyz>4.09985e-05</iyz>
            <izz>6.19092</izz>
          </inertia>
        </inertial>
        <collision name='robot_base_footprint_fixed_joint_lump__robot_base_link_collision'>
          <pose frame=''>0 0 0.11 0 -0 0</pose>
          <geometry>
            <mesh>
              <scale>1 1 1</scale>
              <uri>/home/oj/catkin_ws/src/summit_xl_common/summit_xl_description/meshes/bases/summit_xl_chassis_collision.dae</uri>
            </mesh>
          </geometry>
          <max_contacts>10</max_contacts>
          <surface>
            <contact>
              <ode/>
            </contact>
            <bounce/>
            <friction>
              <torsional>
                <ode/>
              </torsional>
              <ode/>
            </friction>
          </surface>
        </collision>
        <collision name='robot_base_footprint_fixed_joint_lump__robot_front_laser_base_link_collision_1'>
          <pose frame=''>0 0 0.39 0 -0 0</pose>
          <geometry>
            <box>
              <size>0.01 0.01 0.01</size>
            </box>
          </geometry>
          <max_contacts>10</max_contacts>
          <surface>
            <contact>
              <ode/>
            </contact>
            <bounce/>
            <friction>
              <torsional>
                <ode/>
              </torsional>
              <ode/>
            </friction>
          </surface>
        </collision>
        <collision name='robot_base_footprint_fixed_joint_lump__robot_front_ptz_camera_base_link_collision_2'>
          <pose frame=''>0.19 0 0.37 0 0.261799 0</pose>
          <geometry>
            <mesh>
              <scale>1 1 1</scale>
              <uri>/home/oj/catkin_ws/src/robotnik_sensors/meshes/camera_axis_p5514.stl</uri>
            </mesh>
          </geometry>
          <surface>
            <contact>
              <ode/>
            </contact>
            <friction>
              <ode/>
              <torsional>
                <ode/>
              </torsional>
            </friction>
            <bounce/>
          </surface>
          <max_contacts>10</max_contacts>
        </collision>
        <collision name='robot_base_footprint_fixed_joint_lump__robot_front_rgbd_camera_link_collision_3'>
          <pose frame=''>0.324 -0.0005 0.267 0 -0 0</pose>
          <geometry>
            <mesh>
              <scale>1 1 1</scale>
              <uri>/home/oj/catkin_ws/src/robotnik_sensors/meshes/orbbec_astra.dae</uri>
            </mesh>
          </geometry>
          <max_contacts>10</max_contacts>
          <surface>
            <contact>
              <ode/>
            </contact>
            <bounce/>
            <friction>
              <torsional>
                <ode/>
              </torsional>
              <ode/>
            </friction>
          </surface>
        </collision>
        <collision name='robot_base_footprint_fixed_joint_lump__robot_gps_base_link_collision_4'>
          <pose frame=''>-0.22 0 0.385 0 -0 0</pose>
          <geometry>
            <mesh>
              <scale>1 1 1</scale>
              <uri>/home/oj/catkin_ws/src/robotnik_sensors/meshes/antenna_3GO16.stl</uri>
            </mesh>
          </geometry>
          <surface>
            <contact>
              <ode/>
            </contact>
            <friction>
              <ode/>
              <torsional>
                <ode/>
              </torsional>
            </friction>
            <bounce/>
          </surface>
          <max_contacts>10</max_contacts>
        </collision>
        <visual name='robot_base_footprint_visual'>
          <pose frame=''>0 0 0 0 -0 0</pose>
          <geometry>
            <box>
              <size>0.001 0.001 0.001</size>
            </box>
          </geometry>
        </visual>
        <visual name='robot_base_footprint_fixed_joint_lump__robot_base_link_visual_1'>
          <pose frame=''>0 0 0.11 0 -0 0</pose>
          <geometry>
            <mesh>
              <scale>1 1 1</scale>
              <uri>/home/oj/catkin_ws/src/summit_xl_common/summit_xl_description/meshes/bases/summit_xl_chassis.dae</uri>
            </mesh>
          </geometry>
        </visual>
        <visual name='robot_base_footprint_fixed_joint_lump__robot_front_laser_base_link_visual_2'>
          <pose frame=''>0 0 0.39 0 -0 0</pose>
          <geometry>
            <mesh>
              <scale>1 1 1</scale>
              <uri>/home/oj/catkin_ws/src/robotnik_sensors/meshes/hokuyo_ust_10lx.dae</uri>
            </mesh>
          </geometry>
        </visual>
        <visual name='robot_base_footprint_fixed_joint_lump__robot_front_ptz_camera_base_link_visual_3'>
          <pose frame=''>0.19 0 0.37 0 0.261799 0</pose>
          <geometry>
            <mesh>
              <scale>1 1 1</scale>
              <uri>/home/oj/catkin_ws/src/robotnik_sensors/meshes/camera_axis_p5514.stl</uri>
            </mesh>
          </geometry>
          <material>
            <script>
              <name>Gazebo/FlatBlack</name>
              <uri>file://media/materials/scripts/gazebo.material</uri>
            </script>
          </material>
        </visual>
        <visual name='robot_base_footprint_fixed_joint_lump__robot_front_rgbd_camera_link_visual_4'>
          <pose frame=''>0.324 -0.0005 0.267 0 -0 0</pose>
          <geometry>
            <mesh>
              <scale>1 1 1</scale>
              <uri>/home/oj/catkin_ws/src/robotnik_sensors/meshes/orbbec_astra.dae</uri>
            </mesh>
          </geometry>
        </visual>
        <visual name='robot_base_footprint_fixed_joint_lump__robot_gps_base_link_visual_5'>
          <pose frame=''>-0.22 0 0.385 0 -0 0</pose>
          <geometry>
            <mesh>
              <scale>1 1 1</scale>
              <uri>/home/oj/catkin_ws/src/robotnik_sensors/meshes/antenna_3GO16.stl</uri>
            </mesh>
          </geometry>
          <material>
            <script>
              <name>Gazebo/White</name>
              <uri>file://media/materials/scripts/gazebo.material</uri>
            </script>
          </material>
        </visual>
        <visual name='robot_base_footprint_fixed_joint_lump__robot_imu_link_visual_6'>
          <pose frame=''>-0.18 0 0.28 0 -0 0</pose>
          <geometry>
            <box>
              <size>0.001 0.001 0.001</size>
            </box>
          </geometry>
          <material>
            <script>
              <uri>__default__</uri>
              <name>__default__</name>
            </script>
          </material>
        </visual>
        <velocity_decay/>
        <sensor name='robot_front_laser_sensor' type='ray'>
          <visualize>0</visualize>
          <update_rate>40</update_rate>
          <ray>
            <scan>
              <horizontal>
                <samples>1081</samples>
                <resolution>1</resolution>
                <min_angle>-2.3562</min_angle>
                <max_angle>2.3562</max_angle>
              </horizontal>
              <vertical>
                <samples>1</samples>
                <min_angle>0</min_angle>
                <max_angle>0</max_angle>
              </vertical>
            </scan>
            <range>
              <min>0.06</min>
              <max>10</max>
              <resolution>0.0043593</resolution>
            </range>
            <noise>
              <type>gaussian</type>
              <mean>0</mean>
              <stddev>0.01</stddev>
            </noise>
          </ray>
          <plugin name='robot_front_laser_controller' filename='libgazebo_ros_laser.so'>
            <topicName>front_laser/scan</topicName>
            <frameName>/robot_front_laser_link</frameName>
            <robotNamespace>/robot/</robotNamespace>
          </plugin>
          <pose frame=''>0 0 0.44 0 -0 0</pose>
        </sensor>
        <velocity_decay/>
        <velocity_decay/>
        <sensor name='robot_front_rgbd_camera_depth_sensor' type='depth'>
          <always_on>1</always_on>
          <update_rate>20</update_rate>
          <camera name='__default__'>
            <horizontal_fov>1.0472</horizontal_fov>
            <image>
              <format>R8G8B8</format>
              <width>640</width>
              <height>480</height>
            </image>
            <clip>
              <near>0.05</near>
              <far>3.5</far>
            </clip>
          </camera>
          <plugin name='robot_front_rgbd_camera_controller' filename='libgazebo_ros_openni_kinect.so'>
            <cameraName>front_rgbd_camera</cameraName>
            <alwaysOn>1</alwaysOn>
            <updateRate>10</updateRate>
            <imageTopicName>rgb/image_raw</imageTopicName>
            <depthImageTopicName>depth/image_raw</depthImageTopicName>
            <pointCloudTopicName>depth/points</pointCloudTopicName>
            <cameraInfoTopicName>rgb/camera_info</cameraInfoTopicName>
            <depthImageCameraInfoTopicName>depth/camera_info</depthImageCameraInfoTopicName>
            <frameName>/robot_front_rgbd_camera_depth_optical_frame</frameName>
            <baseline>0.1</baseline>
            <distortion_k1>0.0</distortion_k1>
            <distortion_k2>0.0</distortion_k2>
            <distortion_k3>0.0</distortion_k3>
            <distortion_t1>0.0</distortion_t1>
            <distortion_t2>0.0</distortion_t2>
            <pointCloudCutoff>0.4</pointCloudCutoff>
            <robotNamespace>/robot/</robotNamespace>
          </plugin>
          <pose frame=''>0.324 0.012 0.282 0 -0 0</pose>
        </sensor>
        <velocity_decay/>
        <gravity>1</gravity>
        <gravity>1</gravity>
        <velocity_decay/>
        <gravity>1</gravity>
        <sensor name='robot_imu_imu_sensor' type='imu'>
          <always_on>1</always_on>
          <update_rate>100</update_rate>
          <visualize>1</visualize>
          <topic>__default_topic__</topic>
          <plugin name='robot_imu_imu_plugin' filename='libgazebo_ros_imu_sensor.so'>
            <topicName>imu/data</topicName>
            <bodyName>robot_imu_link</bodyName>
            <updateRateHZ>100.0</updateRateHZ>
            <gaussianNoise>0.0</gaussianNoise>
            <xyzOffset>0 0 0</xyzOffset>
            <rpyOffset>0 0 0</rpyOffset>
            <frameName>robot_imu_link</frameName>
            <robotNamespace>/robot/</robotNamespace>
          </plugin>
          <pose frame=''>-0.18 0 0.28 0 -0 0</pose>
          <imu/>
        </sensor>
        <self_collide>0</self_collide>
        <enable_wind>0</enable_wind>
        <kinematic>0</kinematic>
      </link>
      <link name='robot_back_left_wheel'>
        <pose frame=''>-0.229 0.235 0.11 0 -0 0</pose>
        <inertial>
          <pose frame=''>0 0 0 0 -0 0</pose>
          <mass>6.5</mass>
          <inertia>
            <ixx>0.03185</ixx>
            <ixy>0</ixy>
            <ixz>0</ixz>
            <iyy>0.039325</iyy>
            <iyz>0</iyz>
            <izz>0.03185</izz>
          </inertia>
        </inertial>
        <collision name='robot_back_left_wheel_collision'>
          <pose frame=''>0 0 0 1.5708 -0 0</pose>
          <geometry>
            <cylinder>
              <length>0.15</length>
              <radius>0.11</radius>
            </cylinder>
          </geometry>
          <surface>
            <contact>
              <ode>
                <kp>1e+07</kp>
                <kd>1</kd>
              </ode>
            </contact>
            <friction>
              <ode>
                <mu>1</mu>
                <mu2>1</mu2>
                <fdir1>1 0 0</fdir1>
              </ode>
              <torsional>
                <ode/>
              </torsional>
            </friction>
            <bounce/>
          </surface>
          <max_contacts>10</max_contacts>
        </collision>
        <visual name='robot_back_left_wheel_visual'>
          <pose frame=''>0 0 0 0 -0 0</pose>
          <geometry>
            <mesh>
              <scale>1 1 1</scale>
              <uri>/home/oj/catkin_ws/src/summit_xl_common/summit_xl_description/meshes/wheels/rubber_wheel_left.dae</uri>
            </mesh>
          </geometry>
          <material>
            <script>
              <uri>__default__</uri>
              <name>__default__</name>
            </script>
          </material>
        </visual>
        <gravity>1</gravity>
        <velocity_decay/>
        <self_collide>0</self_collide>
        <enable_wind>0</enable_wind>
        <kinematic>0</kinematic>
      </link>
      <joint name='robot_back_left_wheel_joint' type='revolute'>
        <child>robot_back_left_wheel</child>
        <parent>robot_base_footprint</parent>
        <axis>
          <xyz>0 1 0</xyz>
          <limit>
            <lower>-1e+16</lower>
            <upper>1e+16</upper>
          </limit>
          <dynamics>
            <spring_reference>0</spring_reference>
            <spring_stiffness>0</spring_stiffness>
          </dynamics>
          <use_parent_model_frame>1</use_parent_model_frame>
        </axis>
      </joint>
      <link name='robot_back_right_wheel'>
        <pose frame=''>-0.229 -0.235 0.11 0 -0 0</pose>
        <inertial>
          <pose frame=''>0 0 0 0 -0 0</pose>
          <mass>6.5</mass>
          <inertia>
            <ixx>0.03185</ixx>
            <ixy>0</ixy>
            <ixz>0</ixz>
            <iyy>0.039325</iyy>
            <iyz>0</iyz>
            <izz>0.03185</izz>
          </inertia>
        </inertial>
        <collision name='robot_back_right_wheel_collision'>
          <pose frame=''>0 0 0 1.5708 -0 0</pose>
          <geometry>
            <cylinder>
              <length>0.15</length>
              <radius>0.11</radius>
            </cylinder>
          </geometry>
          <surface>
            <contact>
              <ode>
                <kp>1e+07</kp>
                <kd>1</kd>
              </ode>
            </contact>
            <friction>
              <ode>
                <mu>1</mu>
                <mu2>1</mu2>
                <fdir1>1 0 0</fdir1>
              </ode>
              <torsional>
                <ode/>
              </torsional>
            </friction>
            <bounce/>
          </surface>
          <max_contacts>10</max_contacts>
        </collision>
        <visual name='robot_back_right_wheel_visual'>
          <pose frame=''>0 0 0 0 -0 0</pose>
          <geometry>
            <mesh>
              <scale>1 1 1</scale>
              <uri>/home/oj/catkin_ws/src/summit_xl_common/summit_xl_description/meshes/wheels/rubber_wheel_right.dae</uri>
            </mesh>
          </geometry>
          <material>
            <script>
              <uri>__default__</uri>
              <name>__default__</name>
            </script>
          </material>
        </visual>
        <gravity>1</gravity>
        <velocity_decay/>
        <self_collide>0</self_collide>
        <enable_wind>0</enable_wind>
        <kinematic>0</kinematic>
      </link>
      <joint name='robot_back_right_wheel_joint' type='revolute'>
        <child>robot_back_right_wheel</child>
        <parent>robot_base_footprint</parent>
        <axis>
          <xyz>0 1 0</xyz>
          <limit>
            <lower>-1e+16</lower>
            <upper>1e+16</upper>
          </limit>
          <dynamics>
            <spring_reference>0</spring_reference>
            <spring_stiffness>0</spring_stiffness>
          </dynamics>
          <use_parent_model_frame>1</use_parent_model_frame>
        </axis>
      </joint>
      <link name='robot_front_left_wheel'>
        <pose frame=''>0.229 0.235 0.11 0 -0 0</pose>
        <inertial>
          <pose frame=''>0 0 0 0 -0 0</pose>
          <mass>6.5</mass>
          <inertia>
            <ixx>0.03185</ixx>
            <ixy>0</ixy>
            <ixz>0</ixz>
            <iyy>0.039325</iyy>
            <iyz>0</iyz>
            <izz>0.03185</izz>
          </inertia>
        </inertial>
        <collision name='robot_front_left_wheel_collision'>
          <pose frame=''>0 0 0 1.5708 -0 0</pose>
          <geometry>
            <cylinder>
              <length>0.15</length>
              <radius>0.11</radius>
            </cylinder>
          </geometry>
          <surface>
            <contact>
              <ode>
                <kp>1e+07</kp>
                <kd>1</kd>
              </ode>
            </contact>
            <friction>
              <ode>
                <mu>1</mu>
                <mu2>1</mu2>
                <fdir1>1 0 0</fdir1>
              </ode>
              <torsional>
                <ode/>
              </torsional>
            </friction>
            <bounce/>
          </surface>
          <max_contacts>10</max_contacts>
        </collision>
        <visual name='robot_front_left_wheel_visual'>
          <pose frame=''>0 0 0 0 -0 0</pose>
          <geometry>
            <mesh>
              <scale>1 1 1</scale>
              <uri>/home/oj/catkin_ws/src/summit_xl_common/summit_xl_description/meshes/wheels/rubber_wheel_left.dae</uri>
            </mesh>
          </geometry>
          <material>
            <script>
              <uri>__default__</uri>
              <name>__default__</name>
            </script>
          </material>
        </visual>
        <gravity>1</gravity>
        <velocity_decay/>
        <self_collide>0</self_collide>
        <enable_wind>0</enable_wind>
        <kinematic>0</kinematic>
      </link>
      <joint name='robot_front_left_wheel_joint' type='revolute'>
        <child>robot_front_left_wheel</child>
        <parent>robot_base_footprint</parent>
        <axis>
          <xyz>0 1 0</xyz>
          <limit>
            <lower>-1e+16</lower>
            <upper>1e+16</upper>
          </limit>
          <dynamics>
            <spring_reference>0</spring_reference>
            <spring_stiffness>0</spring_stiffness>
          </dynamics>
          <use_parent_model_frame>1</use_parent_model_frame>
        </axis>
      </joint>
      <link name='robot_front_ptz_camera_pan_link'>
        <pose frame=''>0.19 0 0.37 0 0.261799 0</pose>
        <inertial>
          <pose frame=''>0 0 0 0 -0 0</pose>
          <mass>0.1</mass>
          <inertia>
            <ixx>0.000400833</ixx>
            <ixy>0</ixy>
            <ixz>0</ixz>
            <iyy>0.000400833</iyy>
            <iyz>0</iyz>
            <izz>0.000426666</izz>
          </inertia>
        </inertial>
        <self_collide>0</self_collide>
        <enable_wind>0</enable_wind>
        <kinematic>0</kinematic>
      </link>
      <joint name='robot_front_ptz_camera_pan_joint' type='revolute'>
        <child>robot_front_ptz_camera_pan_link</child>
        <parent>robot_base_footprint</parent>
        <axis>
          <xyz>-0.258819 0 -0.965926</xyz>
          <limit>
            <lower>-3.1415</lower>
            <upper>3.1415</upper>
            <effort>100</effort>
            <velocity>100</velocity>
          </limit>
          <dynamics>
            <spring_reference>0</spring_reference>
            <spring_stiffness>0</spring_stiffness>
          </dynamics>
          <use_parent_model_frame>1</use_parent_model_frame>
        </axis>
      </joint>
      <link name='robot_front_ptz_camera_tilt_link'>
        <pose frame=''>0.19 0 0.37 0 0.261799 0</pose>
        <inertial>
          <pose frame=''>0 0 0 0 -0 0</pose>
          <mass>0.102</mass>
          <inertia>
            <ixx>0.000600833</ixx>
            <ixy>0</ixy>
            <ixz>0</ixz>
            <iyy>0.000600833</iyy>
            <iyz>0</iyz>
            <izz>0.000626666</izz>
          </inertia>
        </inertial>
        <gravity>1</gravity>
        <velocity_decay/>
        <sensor name='robot_front_ptz_camera_sensor' type='camera'>
          <update_rate>30</update_rate>
          <camera name='__default__'>
            <horizontal_fov>1.0472</horizontal_fov>
            <image>
              <format>R8G8B8</format>
              <width>640</width>
              <height>480</height>
            </image>
            <clip>
              <near>0.05</near>
              <far>8</far>
            </clip>
          </camera>
          <plugin name='robot_front_ptz_camera_controller' filename='libgazebo_ros_camera.so'>
            <alwaysOn>1</alwaysOn>
            <updateRate>0.0</updateRate>
            <cameraName>robot_front_ptz_camera</cameraName>
            <imageTopicName>image_raw</imageTopicName>
            <cameraInfoTopicName>camera_info</cameraInfoTopicName>
            <frameName>/robot_front_ptz_camera_optical_frame_link</frameName>
            <hackBaseline>0.0</hackBaseline>
            <distortionK1>0.0</distortionK1>
            <distortionK2>0.0</distortionK2>
            <distortionK3>0.0</distortionK3>
            <distortionT1>0.0</distortionT1>
            <distortionT2>0.0</distortionT2>
            <robotNamespace>/robot/</robotNamespace>
          </plugin>
          <pose frame=''>0 0 0 0 -0 0</pose>
        </sensor>
        <self_collide>0</self_collide>
        <enable_wind>0</enable_wind>
        <kinematic>0</kinematic>
      </link>
      <joint name='robot_front_ptz_camera_tilt_joint' type='revolute'>
        <child>robot_front_ptz_camera_tilt_link</child>
        <parent>robot_front_ptz_camera_pan_link</parent>
        <axis>
          <xyz>0 -1 0</xyz>
          <limit>
            <lower>-1.5708</lower>
            <upper>1.5708</upper>
            <effort>100</effort>
            <velocity>100</velocity>
          </limit>
          <dynamics>
            <spring_reference>0</spring_reference>
            <spring_stiffness>0</spring_stiffness>
          </dynamics>
          <use_parent_model_frame>1</use_parent_model_frame>
        </axis>
      </joint>
      <link name='robot_front_right_wheel'>
        <pose frame=''>0.229 -0.235 0.11 0 -0 0</pose>
        <inertial>
          <pose frame=''>0 0 0 0 -0 0</pose>
          <mass>6.5</mass>
          <inertia>
            <ixx>0.03185</ixx>
            <ixy>0</ixy>
            <ixz>0</ixz>
            <iyy>0.039325</iyy>
            <iyz>0</iyz>
            <izz>0.03185</izz>
          </inertia>
        </inertial>
        <collision name='robot_front_right_wheel_collision'>
          <pose frame=''>0 0 0 1.5708 -0 0</pose>
          <geometry>
            <cylinder>
              <length>0.15</length>
              <radius>0.11</radius>
            </cylinder>
          </geometry>
          <surface>
            <contact>
              <ode>
                <kp>1e+07</kp>
                <kd>1</kd>
              </ode>
            </contact>
            <friction>
              <ode>
                <mu>1</mu>
                <mu2>1</mu2>
                <fdir1>1 0 0</fdir1>
              </ode>
              <torsional>
                <ode/>
              </torsional>
            </friction>
            <bounce/>
          </surface>
          <max_contacts>10</max_contacts>
        </collision>
        <visual name='robot_front_right_wheel_visual'>
          <pose frame=''>0 0 0 0 -0 0</pose>
          <geometry>
            <mesh>
              <scale>1 1 1</scale>
              <uri>/home/oj/catkin_ws/src/summit_xl_common/summit_xl_description/meshes/wheels/rubber_wheel_right.dae</uri>
            </mesh>
          </geometry>
          <material>
            <script>
              <uri>__default__</uri>
              <name>__default__</name>
            </script>
          </material>
        </visual>
        <gravity>1</gravity>
        <velocity_decay/>
        <self_collide>0</self_collide>
        <enable_wind>0</enable_wind>
        <kinematic>0</kinematic>
      </link>
      <joint name='robot_front_right_wheel_joint' type='revolute'>
        <child>robot_front_right_wheel</child>
        <parent>robot_base_footprint</parent>
        <axis>
          <xyz>0 1 0</xyz>
          <limit>
            <lower>-1e+16</lower>
            <upper>1e+16</upper>
          </limit>
          <dynamics>
            <spring_reference>0</spring_reference>
            <spring_stiffness>0</spring_stiffness>
          </dynamics>
          <use_parent_model_frame>1</use_parent_model_frame>
        </axis>
      </joint>
      <plugin name='ros_control' filename='libgazebo_ros_control.so'>
        <robotParam>robot_description</robotParam>
        <controlPeriod>0.001</controlPeriod>
        <robotSimType>gazebo_ros_control/DefaultRobotHWSim</robotSimType>
        <legacyModeNS>1</legacyModeNS>
        <robotNamespace>/robot/</robotNamespace>
      </plugin>
      <static>0</static>
      <plugin name='robot_gps_controller' filename='libhector_gazebo_ros_gps.so'>
        <alwaysOn>1</alwaysOn>
        <updateRate>5</updateRate>
        <frameId>robot_gps_base_link</frameId>
        <topicName>gps/fix</topicName>
        <referenceLatitude>39.5080331</referenceLatitude>
        <referenceLongitude>-0.4619816</referenceLongitude>
        <referenceHeading>90</referenceHeading>
        <velocityTopicName>gps/fix_velocity</velocityTopicName>
        <drift>0.0 0.0 0.0</drift>
        <gaussianNoise>0.00001 0.00001 0.00001</gaussianNoise>
        <velocityDrift>0.00001 0.00001 0.00001</velocityDrift>
        <velocityGaussianNoise>0.00001 0.00001 0.00001</velocityGaussianNoise>
        <robotNamespace>/robot/</robotNamespace>
        <bodyName>robot_base_footprint</bodyName>
        <xyzOffset>0.22 0 -0.385</xyzOffset>
        <rpyOffset>0 -0 0</rpyOffset>
      </plugin>
      <pose frame=''>0 0 0 0 -0 0</pose>
    </model>
    <model name='whs_world'>
      <link name='link_1'>
        <inertial>
          <mass>1</mass>
          <inertia>
            <ixx>0.166667</ixx>
            <ixy>0</ixy>
            <ixz>0</ixz>
            <iyy>0.166667</iyy>
            <iyz>0</iyz>
            <izz>0.166667</izz>
          </inertia>
        </inertial>
        <pose frame=''>-0 0 0 0 -0 0</pose>
        <visual name='visual'>
          <pose frame=''>0 0 0 0 -0 0</pose>
          <geometry>
            <mesh>
              <uri>/home/oj/catkin_ws/src/ero/ero_gz_worlds/whs_world/meshes/whs_world_3D_Modell.dae</uri>
              <scale>1 1 1</scale>
            </mesh>
          </geometry>
          <material>
            <lighting>1</lighting>
            <script>
              <uri>file://media/materials/scripts/gazebo.material</uri>
              <name>Gazebo/Grey</name>
            </script>
          </material>
          <transparency>0</transparency>
          <cast_shadows>1</cast_shadows>
        </visual>
        <collision name='collision'>
          <laser_retro>0</laser_retro>
          <max_contacts>10</max_contacts>
          <pose frame=''>0 0 0 0 -0 0</pose>
          <geometry>
            <mesh>
              <uri>/home/oj/catkin_ws/src/ero/ero_gz_worlds/whs_world/meshes/whs_world_3D_Modell.dae</uri>
              <scale>1 1 1</scale>
            </mesh>
          </geometry>
          <surface>
            <friction>
              <ode>
                <mu>1</mu>
                <mu2>1</mu2>
                <fdir1>0 0 0</fdir1>
                <slip1>0</slip1>
                <slip2>0</slip2>
              </ode>
              <torsional>
                <coefficient>1</coefficient>
                <patch_radius>0</patch_radius>
                <surface_radius>0</surface_radius>
                <use_patch_radius>1</use_patch_radius>
                <ode>
                  <slip>0</slip>
                </ode>
              </torsional>
            </friction>
            <bounce>
              <restitution_coefficient>0</restitution_coefficient>
              <threshold>1e+06</threshold>
            </bounce>
            <contact>
              <collide_without_contact>0</collide_without_contact>
              <collide_without_contact_bitmask>1</collide_without_contact_bitmask>
              <collide_bitmask>1</collide_bitmask>
              <ode>
                <soft_cfm>0</soft_cfm>
                <soft_erp>0.2</soft_erp>
                <kp>1e+13</kp>
                <kd>1</kd>
                <max_vel>0.01</max_vel>
                <min_depth>0</min_depth>
              </ode>
              <bullet>
                <split_impulse>1</split_impulse>
                <split_impulse_penetration_threshold>-0.01</split_impulse_penetration_threshold>
                <soft_cfm>0</soft_cfm>
                <soft_erp>0.2</soft_erp>
                <kp>1e+13</kp>
                <kd>1</kd>
              </bullet>
            </contact>
          </surface>
        </collision>
        <self_collide>0</self_collide>
        <enable_wind>0</enable_wind>
        <kinematic>0</kinematic>
      </link>
      <static>0</static>
      <allow_auto_disable>1</allow_auto_disable>
      <pose frame=''>0.850596 0.454244 0 0 -0 0</pose>
    </model>
    <state world_name='default'>
      <sim_time>78 817000000</sim_time>
      <real_time>102 149210668</real_time>
      <wall_time>1590415905 410415151</wall_time>
      <iterations>78817</iterations>
      <model name='ground_plane'>
        <pose frame=''>0 0 0 0 -0 0</pose>
        <scale>1 1 1</scale>
        <link name='link'>
          <pose frame=''>0 0 0 0 -0 0</pose>
          <velocity>0 0 0 0 -0 0</velocity>
          <acceleration>0 0 0 0 -0 0</acceleration>
          <wrench>0 0 0 0 -0 0</wrench>
        </link>
      </model>
      <model name='robot'>
        <pose frame=''>-2.2e-05 -0 -6e-06 4e-06 2e-06 -0</pose>
        <scale>1 1 1</scale>
        <link name='robot_back_left_wheel'>
          <pose frame=''>-0.229022 0.234999 0.109995 5e-06 -0.000191 -0</pose>
          <velocity>0.000333 -0.001049 0.003004 0.009539 0.003026 5.8e-05</velocity>
          <acceleration>0.661743 -2.10863 5.94265 0.31948 -0.262747 0.115905</acceleration>
          <wrench>4.30133 -13.7061 38.6272 0 -0 0</wrench>
        </link>
        <link name='robot_back_right_wheel'>
          <pose frame=''>-0.229022 -0.235001 0.109993 4e-06 -0.000245 0</pose>
          <velocity>0.000497 -0.001053 -0.001163 0.00957 0.00451 4.6e-05</velocity>
          <acceleration>0.989587 -2.11542 -2.43517 -2.76045 0.446089 -3.05741</acceleration>
          <wrench>6.43232 -13.7502 -15.8286 0 -0 0</wrench>
        </link>
        <link name='robot_base_footprint'>
          <pose frame=''>-2.2e-05 -0 -6e-06 4e-06 2e-06 -0</pose>
          <velocity>-2e-06 2.2e-05 5.2e-05 0.008877 0.003787 0.000546</velocity>
          <acceleration>0.85934 -1.99114 -0.033576 -1.00099 1.24769 1.08906</acceleration>
          <wrench>22.0567 -51.1066 -0.861807 0 -0 0</wrench>
        </link>
        <link name='robot_front_left_wheel'>
          <pose frame=''>0.228978 0.235 0.109994 4e-06 -0.000279 0</pose>
          <velocity>0.00033 -0.000876 0.001268 0.007961 0.003001 6e-05</velocity>
          <acceleration>0.656692 -1.762 2.4904 -2.83088 -0.312858 0.119954</acceleration>
          <wrench>4.2685 -11.453 16.1876 0 -0 0</wrench>
        </link>
        <link name='robot_front_ptz_camera_pan_link'>
          <pose frame=''>0.189979 -2e-06 0.369993 0.16639 -0.203068 2.44719</pose>
          <velocity>0.001395 -0.00315 -0.000669 -2.00518 0.003877 0.450852</velocity>
          <acceleration>2.77545 -6.33617 -1.40727 0.116306 1.36762 -3.09754</acceleration>
          <wrench>0.277545 -0.633616 -0.140727 0 -0 0</wrench>
        </link>
        <link name='robot_front_ptz_camera_tilt_link'>
          <pose frame=''>0.189979 -2e-06 0.369993 0.159567 -0.277946 2.43466</pose>
          <velocity>0.001396 -0.003154 -0.000669 2.04265 -0.740649 -2.10608</velocity>
          <acceleration>2.77616 -6.34359 -1.40722 -1.12276 -0.507861 -0.179401</acceleration>
          <wrench>0.283168 -0.647046 -0.143537 0 -0 0</wrench>
        </link>
        <link name='robot_front_right_wheel'>
          <pose frame=''>0.228978 -0.235001 0.109992 4e-06 -0.000245 0</pose>
          <velocity>0.0005 -0.000871 -0.002904 0.007923 0.004529 4.3e-05</velocity>
          <acceleration>0.994668 -1.75376 -5.89801 0.235796 0.408076 -3.05559</acceleration>
          <wrench>6.46534 -11.3994 -38.337 0 -0 0</wrench>
        </link>
      </model>
      <model name='whs_world'>
        <pose frame=''>1.23463 -0.071324 -0.135495 0.003349 0.00137 0.011707</pose>
        <scale>1 1 1</scale>
        <link name='link_1'>
          <pose frame=''>1.23463 -0.071324 -0.135495 0.003349 0.00137 0.011707</pose>
          <velocity>0.004174 -0.002455 -1.14952 0.028524 0.012058 8.2e-05</velocity>
          <acceleration>-0.016513 0.009214 -9.6668 1.07736 -0.382018 3.09287</acceleration>
          <wrench>-0.016513 0.009214 -9.6668 0 -0 0</wrench>
        </link>
      </model>
      <light name='sun'>
        <pose frame=''>0 0 10 0 -0 0</pose>
      </light>
    </state>
    <gui fullscreen='0'>
      <camera name='user_camera'>
        <pose frame=''>-0.298327 0.107716 29.5983 0 1.5698 -3.13499</pose>
        <view_controller>orbit</view_controller>
        <projection_type>perspective</projection_type>
      </camera>
    </gui>
  </world>
</sdf>
